Workbook
Name _: '[1]???????'!#REF!
Name _: '[1]???????'!#REF!
Name _: [1]_______!#REF!
Name _: '[1]???????'!#REF!
Name _: '[1]???????'!#REF!
Name _: '[1]???????'!#REF!
Name _: '[1]???????'!#REF!
Name _?: '[2]#REF!'!#REF!
Name _?: '[2]#REF!'!#REF!
Name _?: #REF!
Name _?: '[2]#REF!'!#REF!
Name _?: '[2]#REF!'!#REF!
Name _?: '[2]#REF!'!#REF!
Name _?: '[2]#REF!'!#REF!
Name _??: #REF!
Name _???: #REF!
Name _???: #REF!
Name _???: #REF!
Name _???: #REF!
Name _???: #REF!
Name _???: #REF!
Name _???: #REF!
Name _????: #REF!
Name _???_1: #REF!
Name _???_1: #REF!
Name _???_1: #REF!
Name _???_1: #REF!
Name _???_1: #REF!
Name _???_1: #REF!
Name _???_1: #REF!
Name _???_2: #REF!
Name _???_2: #REF!
Name _???_2: #REF!
Name _???_2: #REF!
Name _???_2: #REF!
Name _???_2: #REF!
Name _???_2: #REF!
Name _???_3: #REF!
Name _???_3: #REF!
Name _???_3: #REF!
Name _???_3: #REF!
Name _???_3: #REF!
Name _???_3: #REF!
Name _???_3: #REF!
Name _???_4: #REF!
Name _???_4: #REF!
Name _???_4: #REF!
Name _???_4: #REF!
Name _???_4: #REF!
Name _???_4: #REF!
Name _???_4: #REF!
Name _???_5: #REF!
Name _???_5: #REF!
Name _???_5: #REF!
Name _???_5: #REF!
Name _???_5: #REF!
Name _???_5: #REF!
Name _???_5: #REF!
Name _???_6: #REF!
Name _???_6: #REF!

Sheet FY2024 Target
A1: FY24 PPORF Evaluation Factor and Target per Key
A2: Key | B2: Key Leader | C2: Evaluation Factor | E2: Key Leader | L2: TS | N2: CN | P2: YF | R2: PPS | T2: F3 | V2: SG
E3: FY19 Data | F3: FY20 Tgt | G3: FY20 Data | H3: FY21 Tgt | I3: FY22 Act | J3: FY23 Act | K3: FY24 Tgt | L3: FY23 Act | M3: FY24 Tgt | N3: FY23 Act | O3: FY24 Tgt | P3: FY23 Act | Q3: FY24 Tgt | R3: FY23 Act | S3: FY24 Tgt | T3: FY23 Act | U3: FY24 Tgt | V3: FY23 Act | W3: FY24 Tgt
A4: 1 | B4: SCR | C4: 5S Check Sheet Score (Level 3.5 Work Place) - 99.63 points (FY2022 actual) | E4: 98.63 | F4: 98 | G4: 99.02 | H4: 98 | I4: =AVERAGE(L4,N4,P4,R4,V4) -> #DIV/0!
C5: 5S Check Sheet Score (Hidden Rooms) - 99.86 points (FY2022 actual) | E5: 98.99 | F5: 98 | G5: 98.29 | H5: 98 | I5: =AVERAGE(I4,L5,N5,P5,R5,V5) -> #DIV/0!
C6: Waste segregation (common areas)- 50% reduction of audit findings (from 6 to 3) | I6: =AVERAGE(L6,N6,P6,R6,V6) -> #DIV/0! | L6: n/a | M6: n/a | N6: n/a | O6: n/a | P6: n/a | Q6: n/a | R6: n/a | S6: n/a
C7: Waste segregation (defined / specific areas) - 50% reduction of audit findings (from 2 to 1) | E7: 98.59 | F7: 13 | G7: 9 | H7: 5 | I7: =AVERAGE(L7,N7,P7,R7,V7) -> #DIV/0!
C8: 5S Check Sheet Score (Common Areas) - 98.25 points (FY2022 actual) - for monitoring only | E8: 99.72 | F8: CN -3 TS-1 Others - 0 | G8: 6 | H8: 0 | I8: =AVERAGE(L8,N8,P8,R8,V8) -> #DIV/0! | L8: n/a | M8: n/a | N8: n/a | O8: n/a | P8: n/a | Q8: n/a | R8: n/a | S8: n/a
A9: 4 | B9: STP | C9: Energy Consumption (KwH per $1k sales) | D9: Energy Consumption (KwH per $1k sales) | E9: =631290 -> 631290 | F9: =599726 -> 599726 | G9: 608300 | H9: 590051 | I9: 146.16 | L9: n/a | M9: n/a | N9: n/a | O9: n/a | P9: n/a | Q9: n/a | R9: n/a | S9: n/a
D10: Water Consumption (cu.m) / headcount (Factory 1 and Factory 2) (10% reduction) | E10: 2.03 | F10: 1.97 | G10: 2.03 | H10: 1.9691 | I10: 1.71 | L10: n/a | M10: n/a | N10: n/a | O10: n/a | P10: n/a | Q10: n/a | R10: n/a | S10: n/a
C11: Paper Consumption (reams) (10% reduction) | I11: 134.14
C12: Reduce Inventory variance from actual count vs.YPICS data by 3% reduction | E12: 205 | F12: 205.4 | G12: =L12+N12+P12+R12+V12 -> #VALUE! | H12: 163.55 | I12: 0.36 | P12: n/a | Q12: n/a | R12: n/a | S12: n/a | V12: n/a | W12: n/a
C13: Ink Consumption (5% Reduction in K Php) - for monitoring only | E13: 0.42 | F13: 0.39 | G13: 0.38 | H13: 0.36 | I13: 745.8
C14: Co. Wide Sales Turn Over Rate (For Monitoring only) Formula: = Total Sales ( 12 Months ) Month End Inventory | E14: =12.86/4 -> 3.215 | F14: =11.57/4 -> 2.8925 | G14: 9.52 | H14: 8.568 | I14: 11.4 | R14: n/a | S14: n/a | V14: n/a | W14: n/a
A15: 6 | B15: ROR | C15: Improved Labor Efficiency (DL) - by 5% from FY 2022 actual performance | E15: 1.070675 | F15: 1.0925 | G15: 1.08 | H15: 1.13 | I15: 0.99416852 | R15: n/a | S15: n/a | V15: n/a | W15: n/a
C16: Improved Labor Efficiency (DL + ODL) 3% minimum from FY 2022 actual performance | E16: 0.8396 | F16: 0.89 | G16: 0.85666667 | H16: 0.91 | I16: 0.82626917 | R16: n/a | S16: n/a | V16: n/a | W16: n/a
C17: Value-add sales / manhour - Increase by $0.5/mhr (minimum) | V17: n/a | W17: n/a
C18: Conversion to: Auto / semi auto machine / semi-auto jigs
C19: Machine Efficiency by 5% (PPS) Molding Machine, Stamping & Grinding | D19: PPS-TS | E19: 0.6271 | F19: 0.8 | G19: 0.5 | H19: 0.8 | I19: 0.65 | L19: n/a | M19: n/a | N19: n/a | O19: n/a | P19: n/a | Q19: n/a | V19: n/a | W19: n/a
D20: PPS-CN | I20: 0.75 | L20: n/a | M20: n/a | N20: n/a | O20: n/a | P20: n/a | Q20: n/a | V20: n/a | W20: n/a
C21: Shipment / Report Hit Rate (1st Pass) to 99.30% and over | D21: Automotive | E21: 0.9941 | F21: 0.99643333 | G21: 0.9971 | H21: 1 | I21: 0.99999685 | L21: n/a | M21: n/a | V21: n/a | W21: n/a
D22: Non-automotive | E22: 0.988475 | F22: 0.9929 | G22: 0.995425 | H22: 0.9975 | I22: 0.99703744 | V22: n/a | W22: n/a
D23: Overall Shipment Hit Rate | I23: 0.99719543 | V23: n/a | W23: n/a
D24: SUPPORT GROUP: Based on the Detailed Rule of Organization (DRO) | E24: 1 | F24: 1 | G24: 1 | H24: 1 | I24: 1 | L24: n/a | M24: n/a | N24: n/a | O24: n/a | P24: n/a | Q24: n/a | R24: n/a | S24: n/a
C25: Machine Utilization Rate by 80% - Monitoring only | D25: PPS-TS | I25: 0.58 | L25: n/a | M25: n/a | N25: n/a | O25: n/a | P25: n/a | Q25: n/a | V25: n/a | W25: n/a
D26: PPS-CN | I26: 0.57 | L26: n/a | M26: n/a | N26: n/a | O26: n/a | P26: n/a | Q26: n/a | V26: n/a | W26: n/a
C27: PPS Machine Unplanned Downtime (5%) - for monitoring only | I27: 105.6625 | L27: n/a | M27: n/a | N27: n/a | O27: n/a | P27: n/a | Q27: n/a | V27: n/a | W27: n/a
C28: Line OEE (CN) - Monitoring only (new evaluation factor) | L28: n/a | M28: n/a | P28: n/a | Q28: n/a | R28: n/a | S28: n/a | V28: n/a | W28: n/a
C29: Line Availability (A%) | I29: - | L29: n/a | M29: n/a | P29: n/a | Q29: n/a | R29: n/a | S29: n/a | V29: n/a | W29: n/a
C30: Line Performance (P%) | I30: - | L30: n/a | M30: n/a | P30: n/a | Q30: n/a | R30: n/a | S30: n/a | V30: n/a | W30: n/a
C31: Line Quality (Q%) | I31: - | L31: n/a | M31: n/a | P31: n/a | Q31: n/a | R31: n/a | S31: n/a | V31: n/a | W31: n/a
A32: 11 | B32: RDM | C32: 1. Customer Claim- Class A - Total Weighted AVE: (5%) | E32: 14 | F32: 10 | G32: 18 | H32: 13 | I32: 7 | J32: =L32+N32+P32+R32 -> 10 | K32: =M32+O32+Q32+S32 -> 9 | L32: 2 | M32: 1 | N32: 6 | O32: 6 | P32: 0 | Q32: 0 | R32: 2 | S32: 2 | V32: n/a | W32: n/a
C33: 2. Customer Claim- Class B/C Weighted AVE: (5%) | E33: 12 | F33: 9 | G33: 7 | H33: 6 | I33: 9 | J33: 4 | K33: 4 | L33: 0 | M33: 1 | N33: 3 | O33: 3 | P33: 0 | Q33: 0 | R33: 0 | S33: 0 | V33: n/a | W33: n/a
C34: 3. Internal Customer Claim for Support Group (Weighted AVE: (50%) | E34: 0 | F34: 0 | G34: 0 | H34: 0 | I34: 0 | J34: 0 | K34: 0 | L34: n/a | M34: n/a | N34: n/a | O34: n/a | P34: n/a | Q34: n/a | R34: n/a | S34: n/a | V34: 0 | W34: 0
C35: 3. Internal Customer Claim for Production (Weighted AVE: (5%) | E35: 90 | F35: 45 | G35: 40 | H35: 34 | I35: 31 | J35: =N35+R35 -> 20 | K35: =O35+S35 -> 18 | L35: n/a | M35: n/a | N35: 0 | O35: 3 | P35: n/a | Q35: n/a | R35: 20 | S35: 15 | V35: n/a | W35: n/a
C36: 4. First Pass Dppm (Total) (Weighted AVE: (20%) | E36: 6450 | F36: 4838 | G36: 5873 | H36: 4700 | I36: 3141 | J36: 2478 | K36: 2305 | L36: 668 | M36: 574 | N36: 2405 | O36: 2044 | P36: 432 | Q36: 367 | R36: 2758 | S36: 2649 | V36: n/a | W36: n/a
C37: 4. First Pass Dppm - (Automotive only) (Weighted AVE: (20%) | E37: 6872 | F37: 5154 | G37: 4250 | H37: 3825 | I37: 7019 | J37: 2549 | K37: 2166 | L37: n/a | M37: n/a | N37: 2558 | O37: 2174 | P37: 472 | Q37: 420 | R37: n/a | S37: n/a | V37: n/a | W37: n/a
C38: 5. First Pass Yield - (Total) (Weighted AVE: (20%) | E38: 0.9935 | F38: 0.9948 | G38: 0.9942 | H38: 0.9948 | I38: 0.9969 | J38: 0.9975 | K38: 0.9977 | L38: 0.9993 | M38: 0.9994 | N38: 0.9976 | O38: 0.9981 | P38: 0.9996 | Q38: 0.9998 | R38: 0.9972 | S38: 0.9974 | V38: n/a | W38: n/a
C39: 5. First Pass Yield - (Automotive only) Weighted AVE: (20%) | E39: 0.9931 | F39: 0.9949 | G39: 0.9957 | H39: 0.9961 | I39: 0.993 | J39: 0.9975 | K39: 0.9998 | L39: n/a | M39: n/a | N39: 0.9974 | O39: 0.9984 | P39: 0.9995 | Q39: 0.9996 | R39: n/a | S39: n/a | V39: n/a | W39: n/a
C40: 6. Loss Cost ratio to Sales - (Total) 9Weighted AVE: (20%) | E40: 0.0037 | F40: 0.003 | G40: 0.003 | H40: 0.0028 | I40: 0.0021 | J40: 0.0018 | K40: 0.0016 | L40: 0.001 | M40: 0.001 | N40: 0.0023 | O40: 0.0019 | P40: 0.0003 | Q40: 0.0003 | R40: 0.005 | S40: 0.0045 | V40: n/a | W40: n/a
...

Sheet Tri-color
A1: FY2024 KEY 11 TRI-COLOR EVALUATION
A2: MONTH GROUP | B2: 45383 | D2: 45413 | F2: 45444 | H2: 45474 | J2: 45505 | L2: 45536 | N2: 45566 | P2: 45597 | R2: 45627 | T2: 45658 | V2: 45689 | X2: 45717 | Y2: PPORF LEVEL | Z2: ∆
A4: EMS | B4: 0.53 | D4: 0.98 | Y4: =(0.5/20)*((X4-100%)*100)+4 -> 1.5 | Z4: Un
A5: TS | B5: 0.7 | D5: 0.1 | F5: 0.3 | H5: 0.3 | J5: 0.3179 | Y5: =(0.5/20)*((X5-100%)*100)+4 -> 1.5
A6: PPS | B6: 0.9999 | D6: 1 | F6: 0.7403 | H6: 0.65 | J6: 0.7499 | Y6: =(0.5/20)*((X6-100%)*100)+4 -> 1.5
A7: CN | B7: 1 | D7: 0.95 | F7: 0.95 | H7: 0.8218 | J7: 0.25 | Y7: =(0.5/20)*((X7-100%)*100)+4 -> 1.5 | Z7: Un
A8: YF | B8: 1 | D8: 1 | F8: 1 | H8: 1 | J8: 1 | Y8: =(0.5/20)*((X8-100%)*100)+4 -> 1.5 | Z8: Un
A9: Admin/Support Group/QAD | B9: 1 | D9: 1 | F9: 1 | H9: 1 | J9: 1 | Y9: =(0.5/20)*((X9-100%)*100)+4 -> 1.5 | Z9: Un
A11: COMPANY-WIDE TRI-COLOR | B11: ='Company-wide'!AK229 -> 0.9 | D11: ='Company-wide'!AL229 -> 0.95 | F11: ='Company-wide'!AM229 -> 0.92743499 | H11: ='Company-wide'!AN229 -> 0.65 | J11: 0.85 | AA11: `
A13: COMPANY-WIDE PPORF LEVEL | B13: =(0.5/20)*((B11-100%)*100)+4 -> 3.75 | C13: =(0.5/20)*((C11-100%)*100)+4 -> 1.5 | D13: =(0.5/20)*((D11-100%)*100)+4 -> 3.875 | E13: =(0.5/20)*((E11-100%)*100)+4 -> 1.5 | F13: =(0.5/20)*((F11-100%)*100)+4 -> 3.8185875 | G13: =(0.5/20)*((G11-100%)*100)+4 -> 1.5 | H13: =(0.5/20)*((H11-100%)*100)+4 -> 3.125 | I13: =(0.5/20)*((I11-100%)*100)+4 -> 1.5 | ... X13: =(0.5/20)*((X11-100%)*100)+4 -> 1.5
A15: TRI-COLOR SUMMARY
A16: Green
A17: Yellow
A18: Red
A21: KEY 11 LEVEL | B21: RATING | D21: TRI-COLOR
D22: COLOR | E22: RATE | F22: RATE
A23: 1 | B23: 0 | E23: > 80% | F23: > 80%
A24: 1.5 | B24: 1 ~ 20 | E24: 50% - 79 % | F24: 50% - 79 %
A25: 2 | B25: 21 ~ 40 | E25: < 50% | F25: < 50%
A26: 2.5 | B26: 41 ~ 60
A27: 3 | B27: 61 ~ 80
A28: 3.5 | B28: 81 - 100
A29: 4
A30: 4.5
A31: 5

Sheet Company-wide
A2: =AO229 -> 0.85 | B2: Action Plan | E2: Division / Section: | I2: Company-wide | R2: Ref. No.: | Z2: Approved (sign)
B3: Theme | E3: Responsible Person | I3: Team Members | R3: Date Prepared: | T3: Sept 14, 2024 | Z3: ESM/EAN/RNS
A4: Key 11 | B4: Quality Assurance System | E4: Rita D. Morallos | I4: Joylyn P. / Tristine M. / Carlo P. / Belen P. / Jezelle A. / Armida M. Lina Palencia - Asst Leader | R4: Approval: | T4: RDM
A5: Aiming for Improvement | B5: Slogan | E5: Area | I5: Objective | R5: Evaluation Factor Customer Claim | T5: Evaluation Factor First Pass Yield / Dppm | V5: Evaluation Factor First Pass Yield / Dppm (Automotive) | X5: Evaluation Factor OQC LAR / Dppm | Z5: Evaluation Factor OQC LAR / Dppm (Automotive) | AB5: Evaluation Factor Loss Cost Ratio to Sales | AD5: Evaluation Factor Customer Claim (Internal) | AF5: Evaluation Factor Supplier's Performance
B6: Let's apply QA system on countermeasures at the source | E6: COMPANY-WIDE | I6: <> Boost Efficiency and Quality with Higher YIELD / Lower DPPM for Better Performance | R6: FY23 | S6: FY24Tgt | T6: FY23 | U6: FY24Tgt | V6: FY23 | W6: FY24Tgt | X6: FY23 | Y6: FY24Tgt | Z6: FY23 | AA6: FY24Tgt | AB6: FY23 | AC6: FY24Tgt | AD6: FY23 | AE6: FY24Tgt | AF6: FY23 | AG6: FY24Tgt
I7: <> Enhance Outgoing LAR while Decreasing DPPM | R7: Class A 10 | S7: Class A 9 | T7: 0.9975 | U7: 0.9977 | V7: 0.9975 | W7: 0.9998 | X7: 0.9995 | Y7: 0.9996 | Z7: 0.9996 | AA7: 0.9984 | AB7: 0.0018 | AC7: 0.0016 | AD7: 20 | AE7: 18 | AF7: 0.9973 | AG7: 0.95
I8: <> Customer Satisfaction Enhancement: Minimizing Customer’s Complaints
I9: <> Attainment of Company-Wide Loss Cost Ratio to Sales Goal
R10: Class B/C 4 | S10: Class B/C 4 | T10: 2478 | U10: 2305 | V10: 2549 | W10: 2166 | X10: 11 | Y10: 2 | Z10: 2 | AA10: 2.865
A13: No | B13: Action | E13: Person | F13: Apr | G13: May | H13: Jun | I13: Jul | J13: Aug | K13: Sep | L13: Oct | M13: Nov | N13: Dec | O13: Jan | P13: Feb | Q13: Mar | R13: Follow-up by Responsible Person | Z13: Comments from Manager
A14: 1 | B14: Data consolidation coming from each group. | E14: RDM & Key 11 Members | R14: April 2024 RDM | S14: EF with issue is the OQC LAR & Dppm - implement all actions to prevent reccurence | Z14: April 2024 RNS | AA14: Overall performance is good. Just watch out for OQC LAR/Dppm
A15: 2 | B15: > Implement & monitor the quality improvement per production section as planned. | E15: Key 11 Members (Operations) | R15: May 2024 RDM | S15: TS Section has off target performance (Yield, Loss cost & OQC LAR)- Need to implement all formulated actions per as planned. | Z15: May 2024 RNS | AA15: Please implement all derived actions.
R16: June 2024 RDM | S16: Overall performance is on target. Keep it up. | Z16: June 2024 RNS | AA16: Please implement all derived actions consistently
R17: July 2024 RDM | S17: The Yield & LAR of co-wide declined, thus actions from each section is important to impact to total performance | Z17: July 2024 RNS | AA17: Be mindful of each group's performanxe & implement actions accordingly
R18: Aug 2024 RDM | S18: EF of co-wide is on target even if TS & CN performance is off target | Z18: Aug 2024 RNS | AA18: Continue to derive actions and make a way to implement it.
AJ51: Pink cell should be updated
AH52: Company-Wide
AH53: 1.) Customer Claim (Class A) | AJ53: 45352 | AK53: 45383 | AL53: 45413 | AM53: 45444 | AN53: 45474 | AO53: 45505 | AP53: 45536 | AQ53: 45566 | AR53: 45597 | AS53: 45627 | AT53: 45658 | AU53: 45689 | AV53: 45717
AH54: =(AV54-AJ54)/12 -> 0 | AJ54: =AV54 -> 10 | AK54: =AJ54+$AH$54 -> 10 | AL54: =AK54+$AH$54 -> 10 | AM54: =AL54+$AH$54 -> 10 | AN54: =AM54+$AH$54 -> 10 | AO54: =AN54+$AH$54 -> 10 | AP54: =AO54+$AH$54 -> 10 | AQ54: =AP54+$AH$54 -> 10 | AR54: =AQ54+$AH$54 -> 10 | ... AU54: =AT54+$AH$54 -> 10 | AV54: 10
AH55: =(AV55-AJ55)/12 -> -0.041666667 | AI55: Performance | AJ55: =AV54 -> 10 | AK55: =AJ55+$AH$55 -> 9.9583333 | AL55: =AK55+$AH$55 -> 9.9166667 | AM55: =AL55+$AH$55 -> 9.875 | AN55: =AM55+$AH$55 -> 9.8333333 | AO55: =AN55+$AH$55 -> 9.7916667 | AP55: =AO55+$AH$55 -> 9.75 | AQ55: =AP55+$AH$55 -> 9.7083333 | AR55: =AQ55+$AH$55 -> 9.6666667 | ... AU55: =AT55+$AH$55 -> 9.5416667 | AV55: =AV54-(AV54-AV57)*0.5 -> 9.5
AH56: =(AV56-AJ56)/12 -> -0.066666667 | AI56: Performance | AJ56: =AV54 -> 10 | AK56: =AJ56+$AH$56 -> 9.9333333 | AL56: =AK56+$AH$56 -> 9.8666667 | AM56: =AL56+$AH$56 -> 9.8 | AN56: =AM56+$AH$56 -> 9.7333333 | AO56: =AN56+$AH$56 -> 9.6666667 | AP56: =AO56+$AH$56 -> 9.6 | AQ56: =AP56+$AH$56 -> 9.5333333 | AR56: =AQ56+$AH$56 -> 9.4666667 | ... AU56: =AT56+$AH$56 -> 9.2666667 | AV56: =AV54-(AV54-AV57)*0.8 -> 9.2
AH57: =(AV57-AJ57)/12 -> -0.083333333 | AI57: Performance | AJ57: =AV54 -> 10 | AK57: =AJ57+$AH$57 -> 9.9166667 | AL57: =AK57+$AH$57 -> 9.8333333 | AM57: =AL57+$AH$57 -> 9.75 | AN57: =AM57+$AH$57 -> 9.6666667 | AO57: =AN57+$AH$57 -> 9.5833333 | AP57: =AO57+$AH$57 -> 9.5 | AQ57: =AP57+$AH$57 -> 9.4166667 | AR57: =AQ57+$AH$57 -> 9.3333333 | ... AU57: =AT57+$AH$57 -> 9.0833333 | AV57: 9
AH58: Accum. Actual Performance | AK58: =AK60 -> 0 | AL58: =AK58+AL60 -> 0 | AM58: =AL58+AM60 -> 1 | AN58: =AM58+AN60 -> 2 | AO58: =AN58+AO60 -> 3 | AP58: =AO58+AP60 -> 3 | AQ58: =AP58+AQ60 -> 3 | AR58: =AQ58+AR60 -> 3 | AS58: =AR58+AS60 -> 3 | ... AV58: =AU58+AV60 -> 3
AH60: Actual Performance | AK60: =TS!AG50+PPD!AI59+CN!AK63+YF!AK59 -> 0 | AL60: =TS!AH50+PPD!AJ59+CN!AL63+YF!AL59 -> 0 | AM60: =TS!AI50+PPD!AK59+CN!AM63+YF!AM59 -> 1 | AN60: =TS!AJ50+PPD!AL59+CN!AN63+YF!AN59 -> 1 | AO60: =TS!AK50+PPD!AM59+CN!AO63+YF!AO59 -> 1 | AP60: =TS!AL50+PPD!AN59+CN!AP63+YF!AP59 -> 0 | AQ60: =TS!AM50+PPD!AO59+CN!AQ63+YF!AQ59 -> 0 | AR60: =TS!AN50+PPD!AP59+CN!AR63+YF!AR59 -> 0 | ... AV60: =TS!AR50+PPD!AT59+CN!AV63+YF!AV59 -> 0
AK61: =AK60 -> 0 | AL61: =AL60 -> 0 | AM61: =AM60 -> 1 | AN61: =AN60 -> 1 | AO61: =AO60 -> 1 | AP61: =AP60 -> 0 | AQ61: =AQ60 -> 0 | AR61: =AR60 -> 0 | ... AV61: =AV60 -> 0
AH62: Achievement Rate | AK62: =(AK54-AK58)/(AK54-AK57) -> 120 | AL62: =(AL54-AL58)/(AL54-AL57) -> 60 | AM62: =(AM54-AM58)/(AM54-AM57) -> 36 | AN62: =(AN54-AN58)/(AN54-AN57) -> 24 | AO62: =(AO54-AO58)/(AO54-AO57) -> 16.8 | AP62: =(AP54-AP58)/(AP54-AP57) -> 14 | AQ62: =(AQ54-AQ58)/(AQ54-AQ57) -> 12 | AR62: =(AR54-AR58)/(AR54-AR57) -> 10.5 | ... AV62: =(AV54-AV58)/(AV54-AV57) -> 7
AH63: Achievement Rate (Conditional) | AK63: =IF(OR(AK62>=100%),100%,IF(OR(AK62<=0%),0%,AVERAGE(AK62))) -> 1 | AL63: =IF(OR(AL62>=100%),100%,IF(OR(AL62<=0%),0%,AVERAGE(AL62))) -> 1 | AM63: =IF(OR(AM62>=100%),100%,IF(OR(AM62<=0%),0%,AVERAGE(AM62))) -> 1 | AN63: =IF(OR(AN62>=100%),100%,IF(OR(AN62<=0%),0%,AVERAGE(AN62))) -> 1 | AO63: =IF(OR(AO62>=100%),100%,IF(OR(AO62<=0%),0%,AVERAGE(AO62))) -> 1 | AP63: =IF(OR(AP62>=100%),100%,IF(OR(AP62<=0%),0%,AVERAGE(AP62))) -> 1 | AQ63: =IF(OR(AQ62>=100%),100%,IF(OR(AQ62<=0%),0%,AVERAGE(AQ62))) -> 1 | AR63: =IF(OR(AR62>=100%),100%,IF(OR(AR62<=0%),0%,AVERAGE(AR62))) -> 1 | ... AV63: =IF(OR(AV62>=100%),100%,IF(OR(AV62<=0%),0%,AVERAGE(AV62))) -> 1
AH64: WEIGHTED AVERAGE | AK64: =AK63*0.05 -> 0.05 | AL64: =AL63*0.05 -> 0.05 | AM64: =AM63*0.05 -> 0.05 | AN64: =AN63*0.05 -> 0.05 | AO64: =AO63*0.05 -> 0.05 | AP64: =AP63*0.05 -> 0.05 | AQ64: =AQ63*0.05 -> 0.05 | AR64: =AR63*0.05 -> 0.05 | ... AV64: =AV63*0.05 -> 0.05
AH67: 2) Customer Claim (Class B/C) | AJ67: 45352 | AK67: 45383 | AL67: 45413 | AM67: 45444 | AN67: 45474 | AO67: 45505 | AP67: 45536 | AQ67: 45566 | AR67: 45597 | AS67: 45627 | AT67: 45658 | AU67: 45689 | AV67: 45717
AH68: =(AV68-AJ68)/12 -> 0 | AJ68: =AV68 -> 4 | AK68: =AJ68+$AH$68 -> 4 | AL68: =AK68+$AH$68 -> 4 | AM68: =AL68+$AH$68 -> 4 | AN68: =AM68+$AH$68 -> 4 | AO68: =AN68+$AH$68 -> 4 | AP68: =AO68+$AH$68 -> 4 | AQ68: =AP68+$AH$68 -> 4 | AR68: =AQ68+$AH$68 -> 4 | ... AU68: =AT68+$AH$68 -> 4 | AV68: 4
AH69: =(AV69-AJ69)/12 -> 0 | AI69: Performance | AJ69: =AV68 -> 4 | AK69: =AJ69+$AH$69 -> 4 | AL69: =AK69+$AH$69 -> 4 | AM69: =AL69+$AH$69 -> 4 | AN69: =AM69+$AH$69 -> 4 | AO69: =AN69+$AH$69 -> 4 | AP69: =AO69+$AH$69 -> 4 | AQ69: =AP69+$AH$69 -> 4 | AR69: =AQ69+$AH$69 -> 4 | ... AU69: =AT69+$AH$69 -> 4 | AV69: =AV68-(AV68-AV71)*0.5 -> 4
AH70: =(AV70-AJ70)/12 -> 0 | AI70: Performance | AJ70: =AV68 -> 4 | AK70: =AJ70+$AH$70 -> 4 | AL70: =AK70+$AH$70 -> 4 | AM70: =AL70+$AH$70 -> 4 | AN70: =AM70+$AH$70 -> 4 | AO70: =AN70+$AH$70 -> 4 | AP70: =AO70+$AH$70 -> 4 | AQ70: =AP70+$AH$70 -> 4 | AR70: =AQ70+$AH$70 -> 4 | ... AU70: =AT70+$AH$70 -> 4 | AV70: =AV68-(AV68-AV71)*0.8 -> 4
AH71: =(AV71-AJ71)/12 -> 0 | AI71: Performance | AJ71: =AV68 -> 4 | AK71: =AJ71+$AH$71 -> 4 | AL71: =AK71+$AH$71 -> 4 | AM71: =AL71+$AH$71 -> 4 | AN71: =AM71+$AH$71 -> 4 | AO71: =AN71+$AH$71 -> 4 | AP71: =AO71+$AH$71 -> 4 | AQ71: =AP71+$AH$71 -> 4 | AR71: =AQ71+$AH$71 -> 4 | ... AU71: =AT71+$AH$71 -> 4 | AV71: 4
AH72: Accum. Actual Performance | AK72: =AK74 -> 0 | AL72: =AK72+AL74 -> 1 | AM72: =AL72+AM74 -> 2 | AN72: =AM72+AN74 -> 2 | AO72: =AN72+AO74 -> 2 | AP72: =AO72+AP74 -> 2 | AQ72: =AP72+AQ74 -> 2 | AR72: =AQ72+AR74 -> 2 | AS72: =AR72+AS74 -> 2 | ... AV72: =AU72+AV74 -> 2
AH74: Actual Performance | AK74: =TS!AG64+PPD!AI73+CN!AK77+YF!AK73 -> 0 | AL74: =TS!AH64+PPD!AJ73+CN!AL77+YF!AL73 -> 1 | AM74: =TS!AI64+PPD!AK73+CN!AM77+YF!AM73 -> 1 | AN74: =TS!AJ64+PPD!AL73+CN!AN77+YF!AN73 -> 0 | AO74: =TS!AK64+PPD!AM73+CN!AO77+YF!AO73 -> 0 | AP74: =TS!AL64+PPD!AN73+CN!AP77+YF!AP73 -> 0 | AQ74: =TS!AM64+PPD!AO73+CN!AQ77+YF!AQ73 -> 0 | AR74: =TS!AN64+PPD!AP73+CN!AR77+YF!AR73 -> 0 | ... AV74: =TS!AR64+PPD!AT73+CN!AV77+YF!AV73 -> 0
AK75: =AK74 -> 0 | AL75: =AL74 -> 1 | AM75: =AM74 -> 1 | AN75: =AN74 -> 0 | AO75: =AO74 -> 0 | AP75: =AP74 -> 0 | AQ75: =AQ74 -> 0 | AR75: =AR74 -> 0 | ... AV75: =AV74 -> 0
AH76: Achievement Rate | AK76: 1 | AL76: 1 | AM76: 1 | AN76: 1 | AO76: 1 | AP76: =(AP68-AP72)/(AP68-AP71) -> #DIV/0! | AQ76: =(AQ68-AQ72)/(AQ68-AQ71) -> #DIV/0! | AR76: =(AR68-AR72)/(AR68-AR71) -> #DIV/0! | AS76: =(AS68-AS72)/(AS68-AS71) -> #DIV/0! | AT76: =(AT68-AT72)/(AT68-AT71) -> #DIV/0! | AU76: =(AU68-AU72)/(AU68-AU71) -> #DIV/0! | AV76: =(AV68-AV72)/(AV68-AV71) -> #DIV/0!
AH77: Achievement Rate (Conditional) | AK77: =IF(OR(AK76>=100%),100%,IF(OR(AK76<=0%),0%,AVERAGE(AK76))) -> 1 | AL77: =IF(OR(AL76>=100%),100%,IF(OR(AL76<=0%),0%,AVERAGE(AL76))) -> 1 | AM77: =IF(OR(AM76>=100%),100%,IF(OR(AM76<=0%),0%,AVERAGE(AM76))) -> 1 | AN77: =IF(OR(AN76>=100%),100%,IF(OR(AN76<=0%),0%,AVERAGE(AN76))) -> 1 | AO77: =IF(OR(AO76>=100%),100%,IF(OR(AO76<=0%),0%,AVERAGE(AO76))) -> 1 | AP77: =IF(OR(AP76>=100%),100%,IF(OR(AP76<=0%),0%,AVERAGE(AP76))) -> #DIV/0! | AQ77: =IF(OR(AQ76>=100%),100%,IF(OR(AQ76<=0%),0%,AVERAGE(AQ76))) -> #DIV/0! | AR77: =IF(OR(AR76>=100%),100%,IF(OR(AR76<=0%),0%,AVERAGE(AR76))) -> #DIV/0! | ... AV77: =IF(OR(AV76>=100%),100%,IF(OR(AV76<=0%),0%,AVERAGE(AV76))) -> #DIV/0!
AH78: WEIGHTED AVERAGE | AK78: =AK77*0.05 -> 0.05 | AL78: =AL77*0.05 -> 0.05 | AM78: =AM77*0.05 -> 0.05 | AN78: =AN77*0.05 -> 0.05 | AO78: =AO77*0.05 -> 0.05 | AP78: =AP77*0.05 -> #DIV/0! | AQ78: =AQ77*0.05 -> #DIV/0! | AR78: =AR77*0.05 -> #DIV/0! | ... AV78: =AV77*0.05 -> #DIV/0!
AH80: 3) Internal Claim | AJ80: 45352 | AK80: 45383 | AL80: 45413 | AM80: 45444 | AN80: 45474 | AO80: 45505 | AP80: 45536 | AQ80: 45566 | AR80: 45597 | AS80: 45627 | AT80: 45658 | AU80: 45689 | AV80: 45717
...

Sheet TS
A2: =AK141 -> 0.31788715 | B2: Action Plan | E2: Division / Section: | I2: TS | R2: Ref. No.: | X2: Approved (sign)
B3: Theme | E3: Responsible Person | I3: Team Members | R3: Date Prepared: | T3: 45545 | X3: ESM/EAN/RNS
A4: Key 11 | B4: Quality Assurance System | E4: Armida Monsanto | I4: Kris Poblete, Armida Monsanto, Judith Cataya, Abigail Guttierez, Rai Inocencio, Rose Jewel Bates, Abigail Gutierrez, Joyce Sustento | R4: Approval: | T4: MMM
A5: Aiming for Improvement | B5: Slogan | E5: Area | I5: Objective | R5: Evaluation Factor Customer Claim | T5: Evaluation Factor First Pass Yield / Dppm | V5: Evaluation Factor OQC LAR / Dppm | X5: Evaluation Factor Loss Cost Ratio to Sales
B6: Let's apply QA system on countermeasures at the source | E6: TS | I6: <> Boost Efficiency and Quality with Higher YIELD / Lower DPPM for Better Performance | R6: FY23 | S6: FY 24Tgt | T6: FY23 | U6: FY 24Tgt | V6: FY23 | W6: FY 24Tgt | X6: FY23 | Y6: FY 24Tgt
I7: <> Enhance Outgoing LAR while Decreasing DPPM | R7: Class A 2 | S7: Class A 1 | T7: 0.9993 | U7: 0.9994 | V7: 0.9997 | W7: 0.9997 | X7: 0.001 | Y7: 0.001
I8: <> Customer Satisfaction Enhancement: Minimizing Customer’s Complaints
I9: <> Attainment of Company-Wide Loss Cost Ratio to Sales Goal
R10: Class B/C 0 | S10: Class B/C 1 | T10: 668 | U10: 574 | V10: 5 | W10: 3.5
A13: No | B13: Actions | E13: Person | F13: Apr | G13: May | H13: Jun | I13: Jul | J13: Aug | K13: Sep | L13: Oct | M13: Nov | N13: Dec | O13: Jan | P13: Feb | Q13: Mar | R13: Follow-up by Responsible Person | X13: Comments from Manager
A14: 1 | B14: Prevention of wear and tear for machine critical parts >Implement control and safety level of critical machine parts >Review all machine pre-production check sheets and collaborate with YEC to determine important check points. | E14: DLT / MMM / RDM | R14: April 2024 Armida M. | S14: - Start to implement all action plans based on the set target (reference: FY2024 plans and program). - To check and monitor all actions taken on lot out off target. | X14: April 2024 MMM | Y14: Monitor implementation of generated strategies and actions plans related to quality improvement
A15: 2 | B15: HVT and MPC Machine Modernization >Review all machine pre-production check sheets and collaborate with YEC to determine important check points. | E15: DLT / TS ENGRS | R15: May 2024 Armida M. | S15: - Strictly monitor the implementation of actions taken on all off target evaluation factors. | X15: May 2024 MMM | Y15: Close monitoring shall be conducted to ensure the consistency in implementation of generated actions for OQC lot-out.
A16: 3 | B16: Enhance the certification & training record of Visual Inspectors >Implement interactive way of validation process. >Provide skill map/matrix to easily determine visual inspector current skill. | E16: RDM / KRIS / TRAINERS / HRS / ISS | R16: June 2024 Armida M. | S16: - Check and monitor the consistency on derived actions and improvements on all off target evaluation factors. | X16: June 2024 Armida M. | Y16: - Check and monitor the consistency on derived actions and improvements on all off target evaluation factors.
R17: July 2024 Armida M. | S17: - Continuous monitoring on the consistency and implementation of all generated actions to all off target evaluation factors. | X17: July 2024 MMM | Y17: Close monitoring shall be conducted to ensure the consistency in implementation of generated actions for OQC lot-out.
R18: August 2024 Armida M. | S18: - Strictly monitor the implementation of lot-out & external claim CAPA to improve the total quality performance. | X18: August 2024 MMM | Y18: Ensure the consistent implementation of all generated actions and programs for quality improvement
AF41: Pink cell should be updated
AD42: TS Section
AD43: 1.) Customer Claim (Class A) | AF43: 45352 | AG43: 45383 | AH43: 45413 | AI43: 45444 | AJ43: 45474 | AK43: 45505 | AL43: 45536 | AM43: 45566 | AN43: 45597 | AO43: 45627 | AP43: 45658 | AQ43: 45689 | AR43: 45717
AD44: =(AR44-AF44)/12 -> 0 | AF44: =AR44 -> 2 | AG44: 2 | AH44: =AG44+$AD$44 -> 2 | AI44: =AH44+$AD$44 -> 2 | AJ44: =AI44+$AD$44 -> 2 | AK44: =AJ44+$AD$44 -> 2 | AL44: =AK44+$AD$44 -> 2 | AM44: =AL44+$AD$44 -> 2 | AN44: =AM44+$AD$44 -> 2 | AO44: =AN44+$AD$44 -> 2 | ... AQ44: =AP44+$AD$44 -> 2 | AR44: 2
AD45: =(AR45-AF45)/12 -> 0 | AE45: Performance | AF45: =AR44 -> 2 | AG45: 2 | AH45: =AG45+$AD$45 -> 2 | AI45: =AH45+$AD$45 -> 2 | AJ45: =AI45+$AD$45 -> 2 | AK45: =AJ45+$AD$45 -> 2 | AL45: =AK45+$AD$45 -> 2 | AM45: =AL45+$AD$45 -> 2 | AN45: =AM45+$AD$45 -> 2 | AO45: =AN45+$AD$45 -> 2 | ... AQ45: =AP45+$AD$45 -> 2 | AR45: =AR44-(AR44-AR47)*0.5 -> 2
AD46: =(AR46-AF46)/12 -> 0 | AE46: Performance | AF46: =AR44 -> 2 | AG46: 2 | AH46: =AG46+$AD$46 -> 2 | AI46: =AH46+$AD$46 -> 2 | AJ46: =AI46+$AD$46 -> 2 | AK46: =AJ46+$AD$46 -> 2 | AL46: =AK46+$AD$46 -> 2 | AM46: =AL46+$AD$46 -> 2 | AN46: =AM46+$AD$46 -> 2 | AO46: =AN46+$AD$46 -> 2 | ... AQ46: =AP46+$AD$46 -> 2 | AR46: =AR44-(AR44-AR47)*0.8 -> 2
AD47: =(AR47-AF47)/12 -> 0 | AE47: Performance | AF47: =AR44 -> 2 | AG47: 2 | AH47: =AG47+$AD$47 -> 2 | AI47: =AH47+$AD$47 -> 2 | AJ47: =AI47+$AD$47 -> 2 | AK47: =AJ47+$AD$47 -> 2 | AL47: =AK47+$AD$47 -> 2 | AM47: =AL47+$AD$47 -> 2 | AN47: =AM47+$AD$47 -> 2 | AO47: =AN47+$AD$47 -> 2 | ... AQ47: =AP47+$AD$47 -> 2 | AR47: 2
AD48: Accum. Actual Performance | AG48: 0 | AH48: =AG48+AH50 -> 0 | AI48: =AH48+AI50 -> 0 | AJ48: =AI48+AJ50 -> 1 | AK48: =AJ48+AK50 -> 1 | AL48: =AK48+AL50 -> 1 | AM48: =AL48+AM50 -> 1 | AN48: =AM48+AN50 -> 1 | AO48: =AN48+AO50 -> 1 | ... AR48: =AQ48+AR50 -> 1
AD50: Actual Performance | AG50: 0 | AH50: 0 | AI50: 0 | AJ50: 1 | AK50: 0
AG51: 0 | AH51: =AH50 -> 0 | AI51: =AI50 -> 0 | AJ51: =AJ50 -> 1 | AK51: =AK50 -> 0 | AL51: =AL50 -> 0 | AM51: =AM50 -> 0 | AN51: =AN50 -> 0 | AO51: =AO50 -> 0 | ... AR51: =AR50 -> 0
AD52: Achievement Rate | AG52: 1 | AH52: 1 | AI52: 1 | AJ52: =(AJ44-AJ48)/(AJ44-AJ47) -> #DIV/0! | AK52: =(AK44-AK48)/(AK44-AK47) -> #DIV/0! | AL52: =(AL44-AL48)/(AL44-AL47) -> #DIV/0! | AM52: =(AM44-AM48)/(AM44-AM47) -> #DIV/0! | AN52: =(AN44-AN48)/(AN44-AN47) -> #DIV/0! | AO52: =(AO44-AO48)/(AO44-AO47) -> #DIV/0! | AP52: =(AP44-AP48)/(AP44-AP47) -> #DIV/0! | AQ52: =(AQ44-AQ48)/(AQ44-AQ47) -> #DIV/0! | AR52: =(AR44-AR48)/(AR44-AR47) -> #DIV/0!
AD53: Achievement Rate (Conditional) | AG53: 1 | AH53: 1 | AI53: =IF(OR(AI52>=100%),100%,IF(OR(AI52<=0%),0%,AVERAGE(AI52))) -> 1 | AJ53: 1 | AK53: 0 | AL53: =IF(OR(AL52>=100%),100%,IF(OR(AL52<=0%),0%,AVERAGE(AL52))) -> #DIV/0! | AM53: =IF(OR(AM52>=100%),100%,IF(OR(AM52<=0%),0%,AVERAGE(AM52))) -> #DIV/0! | AN53: =IF(OR(AN52>=100%),100%,IF(OR(AN52<=0%),0%,AVERAGE(AN52))) -> #DIV/0! | AO53: =IF(OR(AO52>=100%),100%,IF(OR(AO52<=0%),0%,AVERAGE(AO52))) -> #DIV/0! | AP53: =IF(OR(AP52>=100%),100%,IF(OR(AP52<=0%),0%,AVERAGE(AP52))) -> #DIV/0! | AQ53: =IF(OR(AQ52>=100%),100%,IF(OR(AQ52<=0%),0%,AVERAGE(AQ52))) -> #DIV/0! | AR53: =IF(OR(AR52>=100%),100%,IF(OR(AR52<=0%),0%,AVERAGE(AR52))) -> #DIV/0!
AD54: WEIGHTED AVERAGE | AG54: =AG53*0.05 -> 0.05 | AH54: =AH53*0.05 -> 0.05 | AI54: =AI53*0.05 -> 0.05 | AJ54: =AJ53*0.05 -> 0.05 | AK54: =AK53*0.05 -> 0 | AL54: =AL53*0.05 -> #DIV/0! | AM54: =AM53*0.05 -> #DIV/0! | AN54: =AN53*0.05 -> #DIV/0! | ... AR54: =AR53*0.05 -> #DIV/0!
AD57: 2) Customer Claim (Class B/C) | AF57: 45352 | AG57: 45383 | AH57: 45413 | AI57: 45444 | AJ57: 45474 | AK57: 45505 | AL57: 45536 | AM57: 45566 | AN57: 45597 | AO57: 45627 | AP57: 45658 | AQ57: 45689 | AR57: 45717
AD58: =(AR58-AF58)/12 -> 0 | AF58: =AR58 -> 0 | AG58: 0 | AH58: =AG58+$AD$58 -> 0 | AI58: =AH58+$AD$58 -> 0 | AJ58: =AI58+$AD$58 -> 0 | AK58: =AJ58+$AD$58 -> 0 | AL58: =AK58+$AD$58 -> 0 | AM58: =AL58+$AD$58 -> 0 | AN58: =AM58+$AD$58 -> 0 | AO58: =AN58+$AD$58 -> 0 | ... AQ58: =AP58+$AD$58 -> 0 | AR58: 0
AD59: =(AR59-AF59)/12 -> 0.041666667 | AE59: Performance | AF59: =AR58 -> 0 | AG59: 0.041666667 | AH59: =AG59+$AD$59 -> 0.083333333 | AI59: =AH59+$AD$59 -> 0.125 | AJ59: =AI59+$AD$59 -> 0.16666667 | AK59: =AJ59+$AD$59 -> 0.20833333 | AL59: =AK59+$AD$59 -> 0.25 | AM59: =AL59+$AD$59 -> 0.29166667 | AN59: =AM59+$AD$59 -> 0.33333333 | AO59: =AN59+$AD$59 -> 0.375 | ... AQ59: =AP59+$AD$59 -> 0.45833333 | AR59: =AR58-(AR58-AR61)*0.5 -> 0.5
AD60: =(AR60-AF60)/12 -> 0.066666667 | AE60: Performance | AF60: =AR58 -> 0 | AG60: 0.066666667 | AH60: =AG60+$AD$60 -> 0.13333333 | AI60: =AH60+$AD$60 -> 0.2 | AJ60: =AI60+$AD$60 -> 0.26666667 | AK60: =AJ60+$AD$60 -> 0.33333333 | AL60: =AK60+$AD$60 -> 0.4 | AM60: =AL60+$AD$60 -> 0.46666667 | AN60: =AM60+$AD$60 -> 0.53333333 | AO60: =AN60+$AD$60 -> 0.6 | ... AQ60: =AP60+$AD$60 -> 0.73333333 | AR60: =AR58-(AR58-AR61)*0.8 -> 0.8
AD61: =(AR61-AF61)/12 -> 0.083333333 | AE61: Performance | AF61: =AR58 -> 0 | AG61: 0.083333333 | AH61: =AG61+$AD$61 -> 0.16666667 | AI61: =AH61+$AD$61 -> 0.25 | AJ61: =AI61+$AD$61 -> 0.33333333 | AK61: =AJ61+$AD$61 -> 0.41666667 | AL61: =AK61+$AD$61 -> 0.5 | AM61: =AL61+$AD$61 -> 0.58333333 | AN61: =AM61+$AD$61 -> 0.66666667 | AO61: =AN61+$AD$61 -> 0.75 | ... AQ61: =AP61+$AD$61 -> 0.91666667 | AR61: 1
AD62: Accum. Actual Performance | AG62: 0 | AH62: =AG62+AH64 -> 0 | AI62: =AH62+AI64 -> 0 | AJ62: =AI62+AJ64 -> 0 | AK62: =AJ62+AK64 -> 0 | AL62: =AK62+AL64 -> 0 | AM62: =AL62+AM64 -> 0 | AN62: =AM62+AN64 -> 0 | AO62: =AN62+AO64 -> 0 | ... AR62: =AQ62+AR64 -> 0
AD64: Actual Performance | AG64: 0 | AH64: 0 | AI64: 0 | AJ64: 0 | AK64: 0
AG65: 0 | AH65: =AH64 -> 0 | AI65: =AI64 -> 0 | AJ65: =AJ64 -> 0 | AK65: =AK64 -> 0 | AL65: =AL64 -> 0 | AM65: =AM64 -> 0 | AN65: =AN64 -> 0 | AO65: =AO64 -> 0 | ... AR65: =AR64 -> 0
AD66: Achievement Rate | AG66: =(AG58-AG62)/(AG58-AG61) -> 0 | AH66: =(AH58-AH62)/(AH58-AH61) -> 0 | AI66: =(AI58-AI62)/(AI58-AI61) -> 0 | AJ66: =(AJ58-AJ62)/(AJ58-AJ61) -> 0 | AK66: =(AK58-AK62)/(AK58-AK61) -> 0 | AL66: =(AL58-AL62)/(AL58-AL61) -> 0 | AM66: =(AM58-AM62)/(AM58-AM61) -> 0 | AN66: =(AN58-AN62)/(AN58-AN61) -> 0 | ... AR66: =(AR58-AR62)/(AR58-AR61) -> 0
AD67: Achievement Rate (Conditional) | AG67: 1 | AH67: 1 | AI67: 1 | AJ67: 1 | AK67: 1 | AL67: =IF(OR(AL66>=100%),100%,IF(OR(AL66<=0%),0%,AVERAGE(AL66))) -> 0 | AM67: =IF(OR(AM66>=100%),100%,IF(OR(AM66<=0%),0%,AVERAGE(AM66))) -> 0 | AN67: =IF(OR(AN66>=100%),100%,IF(OR(AN66<=0%),0%,AVERAGE(AN66))) -> 0 | AO67: =IF(OR(AO66>=100%),100%,IF(OR(AO66<=0%),0%,AVERAGE(AO66))) -> 0 | AP67: =IF(OR(AP66>=100%),100%,IF(OR(AP66<=0%),0%,AVERAGE(AP66))) -> 0 | AQ67: =IF(OR(AQ66>=100%),100%,IF(OR(AQ66<=0%),0%,AVERAGE(AQ66))) -> 0 | AR67: =IF(OR(AR66>=100%),100%,IF(OR(AR66<=0%),0%,AVERAGE(AR66))) -> 0
AD68: WEIGHTED AVERAGE | AG68: =AG67*0.05 -> 0.05 | AH68: =AH67*0.05 -> 0.05 | AI68: =AI67*0.05 -> 0.05 | AJ68: =AJ67*0.05 -> 0.05 | AK68: =AK67*0.05 -> 0.05 | AL68: =AL67*0.05 -> 0 | AM68: =AM67*0.05 -> 0 | AN68: =AN67*0.05 -> 0 | ... AR68: =AR67*0.05 -> 0
AD71: 3.) FIRST PASS Yield - Dppm | AF71: 45352 | AG71: 45383 | AH71: 45413 | AI71: 45444 | AJ71: 45474 | AK71: 45505 | AL71: 45536 | AM71: 45566 | AN71: 45597 | AO71: 45627 | AP71: 45658 | AQ71: 45689 | AR71: 45717
...

Sheet CN
A2: =AO220 -> 0.25 | B2: Action Plan | E2: Division / Section: | I2: CN | R2: Ref. No.: | Z2: Approved (sign)
B3: Theme | E3: Responsible Person | I3: Team Members | R3: Date Prepared: | T3: 45545 | Z3: ESM/EAN/RNS
A4: Key 11 | B4: Quality Assurance System | E4: Tristine Mabulac | I4: Cecille A. / Ramil A. / Mary Joy M. / Angelito DP / Vallerie L. | R4: Approval: | T4: ROR
A5: Aiming for Improvement | B5: Slogan | E5: Area | I5: Objective | R5: Evaluation Factor Customer Claim | T5: Evaluation Factor First Pass Yield / Dppm | V5: Evaluation Factor First Pass Yield / Dppm (Automotive) | X5: Evaluation Factor OQC LAR / Dppm | Z5: Evaluation Factor OQC LAR / Dppm (Automotive) | AB5: Evaluation Factor Loss Cost Ratio to Sales | AD5: Evaluation Factor Customer Claim (Internal)
B6: Let's apply QA system on countermeasures at the source | E6: CN | I6: <> Boost Efficiency and Quality with Higher YIELD / Lower DPPM for Better Performance | R6: FY23 | S6: FY 24Tgt | T6: FY23 | U6: FY 24Tgt | V6: FY23 | W6: FY 24Tgt | X6: FY23 | Y6: FY 24Tgt | Z6: FY23 | AA6: FY 24Tgt | AB6: FY23 | AC6: FY 24Tgt | AD6: FY23 | AE6: FY 24Tgt
I7: <> Enhance Outgoing LAR while Decreasing DPPM | R7: Class A 6 | S7: Class A 6 | T7: 0.9976 | U7: 0.9981 | V7: 0.9974 | W7: 0.9984 | X7: 0.999 | Y7: 0.9994 | Z7: 0.9996 | AA7: 0.9991 | AB7: 0.0023 | AC7: 0.0019 | AD7: 0 | AE7: 3
I8: <> Customer Satisfaction Enhancement: Minimizing Customer’s Complaints
I9: <> Attainment of Company-Wide Loss Cost Ratio to Sales Goal
R10: Class B/C 3 | S10: Class B/C 3 | T10: 2405 | U10: 2044 | V10: 2558 | W10: 2174 | X10: 3 | Y10: 3.3 | Z10: 2 | AA10: 0
A13: No | B13: Action | E13: Person | F13: Apr | G13: May | H13: Jun | I13: Jul | J13: Aug | K13: Sep | L13: Oct | M13: Nov | N13: Dec | O13: Jan | P13: Feb | Q13: Mar | R13: Follow-up by Responsible Person | Z13: Comments from Manager
A14: 1 | B14: 1. Train and certify to all product category (assembly & visual) 2. Train and certify in basic auditing course 2.1 Conduct station check (daily) 2.2 Structure basic close-loop reporting system 3. Implement use of cap with blue lining as identification of Cross-Line-Operator (CLO) | E14: Cecille A. / Val L. / Tristine M. | R14: 45383 | S14: Continue activity as per plan. | Z14: ROR | AA14: > Implement actions to improve OQC LAR/Dppm for non-automotive products.
A15: 2 | B15: Mobile 3D Coplanarity Inspection & Emboss Packing M/C | E15: A. De Pedro / ROR | R15: 45413 | S15: Continous implementation to improvement actions for all evaluation factors. | Z15: ROR | AA15: > Implement actions to improve OQC LAR/Dppm for non-automotive products.
A16: 3 | B16: Visual Inspection Automation using IV2 Camera | E16: A. De Pedro / ROR | R16: 45444 | S16: Continue activity as per plan. | Z16: ROR | AA16: > Provide improvement actions to improve Yield & OQC LAR/Dppm
A17: 4 | B17: PJS008 - 21 Automation | E17: Angelito DP / KTE / ROR | R17: 45474 | S17: Continue activity as per plan. | Z17: ROR | AA17: > Implementation of Spike Control across the CN
A18: 5 | B18: AAT Improvement thru automation | E18: Angelito DP / Engelbert S / Andy U / Valerie L | R18: 45505 | S18: Convene with the team to derived actions to improve Yield & OQC/LAR Dppm | Z18: ROR | AA18: > Provide improvement actions to improve Yield & OQC LAR/Dppm
A19: 6 | B19: Cellular Line Layout | E19: Angelito DP / C. Dominguez
AJ54: Pink cell should be updated
AH55: CN Section
AH56: 1.) Customer Claim (Class A) | AJ56: 45352 | AK56: 45383 | AL56: 45413 | AM56: 45444 | AN56: 45474 | AO56: 45505 | AP56: 45536 | AQ56: 45566 | AR56: 45597 | AS56: 45627 | AT56: 45658 | AU56: 45689 | AV56: 45717
AH57: =(AV57-AJ57)/12 -> 0 | AJ57: =AV57 -> 6 | AK57: 6 | AL57: =AK57+$AH$57 -> 6 | AM57: =AL57+$AH$57 -> 6 | AN57: =AM57+$AH$57 -> 6 | AO57: =AN57+$AH$57 -> 6 | AP57: =AO57+$AH$57 -> 6 | AQ57: =AP57+$AH$57 -> 6 | AR57: =AQ57+$AH$57 -> 6 | AS57: =AR57+$AH$57 -> 6 | ... AU57: =AT57+$AH$57 -> 6 | AV57: 6
AH58: =(AV58-AJ58)/12 -> 0 | AI58: Performance | AJ58: =AV57 -> 6 | AK58: 6 | AL58: =AK58+$AH$58 -> 6 | AM58: =AL58+$AH$58 -> 6 | AN58: =AM58+$AH$58 -> 6 | AO58: =AN58+$AH$58 -> 6 | AP58: =AO58+$AH$58 -> 6 | AQ58: =AP58+$AH$58 -> 6 | AR58: =AQ58+$AH$58 -> 6 | AS58: =AR58+$AH$58 -> 6 | ... AU58: =AT58+$AH$58 -> 6 | AV58: =AV57-(AV57-AV60)*0.5 -> 6
AH59: =(AV59-AJ59)/12 -> 0 | AI59: Performance | AJ59: =AV57 -> 6 | AK59: 6 | AL59: =AK59+$AH$59 -> 6 | AM59: =AL59+$AH$59 -> 6 | AN59: =AM59+$AH$59 -> 6 | AO59: =AN59+$AH$59 -> 6 | AP59: =AO59+$AH$59 -> 6 | AQ59: =AP59+$AH$59 -> 6 | AR59: =AQ59+$AH$59 -> 6 | AS59: =AR59+$AH$59 -> 6 | ... AU59: =AT59+$AH$59 -> 6 | AV59: =AV57-(AV57-AV60)*0.8 -> 6
AH60: =(AV60-AJ60)/12 -> 0 | AI60: Performance | AJ60: =AV57 -> 6 | AK60: 6 | AL60: =AK60+$AH$60 -> 6 | AM60: =AL60+$AH$60 -> 6 | AN60: =AM60+$AH$60 -> 6 | AO60: =AN60+$AH$60 -> 6 | AP60: =AO60+$AH$60 -> 6 | AQ60: =AP60+$AH$60 -> 6 | AR60: =AQ60+$AH$60 -> 6 | AS60: =AR60+$AH$60 -> 6 | ... AU60: =AT60+$AH$60 -> 6 | AV60: 6
AH61: Accum. Actual Performance | AK61: 0 | AL61: =AK61+AL63 -> 0 | AM61: =AL61+AM63 -> 1 | AN61: =AM61+AN63 -> 1 | AO61: =AN61+AO63 -> 1 | AP61: =AO61+AP63 -> 1 | AQ61: =AP61+AQ63 -> 1 | AR61: =AQ61+AR63 -> 1 | AS61: =AR61+AS63 -> 1 | ... AV61: =AU61+AV63 -> 1
AH63: Actual Performance | AK63: 0 | AL63: 0 | AM63: 1 | AN63: 0 | AO63: 0
AK64: 0 | AL64: =AL63 -> 0 | AM64: =AM63 -> 1 | AN64: =AN63 -> 0 | AO64: =AO63 -> 0 | AP64: =AP63 -> 0 | AQ64: =AQ63 -> 0 | AR64: =AR63 -> 0 | AS64: =AS63 -> 0 | ... AV64: =AV63 -> 0
AH65: Achievement Rate | AK65: #DIV/0! | AL65: =(AL57-AL61)/(AL57-AL60) -> #DIV/0! | AM65: =(AM57-AM61)/(AM57-AM60) -> #DIV/0! | AN65: =(AN57-AN61)/(AN57-AN60) -> #DIV/0! | AO65: =(AO57-AO61)/(AO57-AO60) -> #DIV/0! | AP65: =(AP57-AP61)/(AP57-AP60) -> #DIV/0! | AQ65: =(AQ57-AQ61)/(AQ57-AQ60) -> #DIV/0! | AR65: =(AR57-AR61)/(AR57-AR60) -> #DIV/0! | AS65: =(AS57-AS61)/(AS57-AS60) -> #DIV/0! | ... AV65: =(AV57-AV61)/(AV57-AV60) -> #DIV/0!
AH66: Achievement Rate (Conditional) | AK66: 1 | AL66: 1 | AM66: 1 | AN66: 1 | AO66: 1 | AP66: =IF(OR(AP65>=100%),100%,IF(OR(AP65<=0%),0%,AVERAGE(AP65))) -> #DIV/0! | AQ66: =IF(OR(AQ65>=100%),100%,IF(OR(AQ65<=0%),0%,AVERAGE(AQ65))) -> #DIV/0! | AR66: =IF(OR(AR65>=100%),100%,IF(OR(AR65<=0%),0%,AVERAGE(AR65))) -> #DIV/0! | AS66: =IF(OR(AS65>=100%),100%,IF(OR(AS65<=0%),0%,AVERAGE(AS65))) -> #DIV/0! | AT66: =IF(OR(AT65>=100%),100%,IF(OR(AT65<=0%),0%,AVERAGE(AT65))) -> #DIV/0! | AU66: =IF(OR(AU65>=100%),100%,IF(OR(AU65<=0%),0%,AVERAGE(AU65))) -> #DIV/0! | AV66: =IF(OR(AV65>=100%),100%,IF(OR(AV65<=0%),0%,AVERAGE(AV65))) -> #DIV/0!
AG67: 5 | AH67: WEIGHTED AVERAGE | AK67: =AK66*0.05 -> 0.05 | AL67: =AL66*0.05 -> 0.05 | AM67: =AM66*0.05 -> 0.05 | AN67: =AN66*0.05 -> 0.05 | AO67: =AO66*0.05 -> 0.05 | AP67: =AP66*0.05 -> #DIV/0! | AQ67: =AQ66*0.05 -> #DIV/0! | AR67: =AR66*0.05 -> #DIV/0! | ... AV67: =AV66*0.05 -> #DIV/0!
AH70: 2) Customer Claim (Class B/C) | AJ70: 45352 | AK70: 45383 | AL70: 45413 | AM70: 45444 | AN70: 45474 | AO70: 45505 | AP70: 45536 | AQ70: 45566 | AR70: 45597 | AS70: 45627 | AT70: 45658 | AU70: 45689 | AV70: 45717
AH71: =(AV71-AJ71)/12 -> 0 | AJ71: =AV71 -> 3 | AK71: 6 | AL71: =AK71+$AH$71 -> 6 | AM71: =AL71+$AH$71 -> 6 | AN71: =AM71+$AH$71 -> 6 | AO71: =AN71+$AH$71 -> 6 | AP71: =AO71+$AH$71 -> 6 | AQ71: =AP71+$AH$71 -> 6 | AR71: =AQ71+$AH$71 -> 6 | AS71: =AR71+$AH$71 -> 6 | ... AU71: =AT71+$AH$71 -> 6 | AV71: 3
AH72: =(AV72-AJ72)/12 -> 0 | AI72: Performance | AJ72: =AV71 -> 3 | AK72: 6 | AL72: =AK72+$AH$72 -> 6 | AM72: =AL72+$AH$72 -> 6 | AN72: =AM72+$AH$72 -> 6 | AO72: =AN72+$AH$72 -> 6 | AP72: =AO72+$AH$72 -> 6 | AQ72: =AP72+$AH$72 -> 6 | AR72: =AQ72+$AH$72 -> 6 | AS72: =AR72+$AH$72 -> 6 | ... AU72: =AT72+$AH$72 -> 6 | AV72: =AV71-(AV71-AV74)*0.5 -> 3
AH73: =(AV73-AJ73)/12 -> 0 | AI73: Performance | AJ73: =AV71 -> 3 | AK73: 6 | AL73: =AK73+$AH$73 -> 6 | AM73: =AL73+$AH$73 -> 6 | AN73: =AM73+$AH$73 -> 6 | AO73: =AN73+$AH$73 -> 6 | AP73: =AO73+$AH$73 -> 6 | AQ73: =AP73+$AH$73 -> 6 | AR73: =AQ73+$AH$73 -> 6 | AS73: =AR73+$AH$73 -> 6 | ... AU73: =AT73+$AH$73 -> 6 | AV73: =AV71-(AV71-AV74)*0.8 -> 3
AH74: =(AV74-AJ74)/12 -> 0 | AI74: Performance | AJ74: =AV71 -> 3 | AK74: 6 | AL74: =AK74+$AH$74 -> 6 | AM74: =AL74+$AH$74 -> 6 | AN74: =AM74+$AH$74 -> 6 | AO74: =AN74+$AH$74 -> 6 | AP74: =AO74+$AH$74 -> 6 | AQ74: =AP74+$AH$74 -> 6 | AR74: =AQ74+$AH$74 -> 6 | AS74: =AR74+$AH$74 -> 6 | ... AU74: =AT74+$AH$74 -> 6 | AV74: 3
AH75: Accum. Actual Performance | AK75: 0 | AL75: =AK75+AL77 -> 1 | AM75: =AL75+AM77 -> 2 | AN75: =AM75+AN77 -> 2 | AO75: =AN75+AO77 -> 2 | AP75: =AO75+AP77 -> 2 | AQ75: =AP75+AQ77 -> 2 | AR75: =AQ75+AR77 -> 2 | AS75: =AR75+AS77 -> 2 | ... AV75: =AU75+AV77 -> 2
AH77: Actual Performance | AK77: 0 | AL77: 1 | AM77: 1 | AN77: 0 | AO77: 0
AK78: 0 | AL78: =AL77 -> 1 | AM78: =AM77 -> 1 | AN78: =AN77 -> 0 | AO78: =AO77 -> 0 | AP78: =AP77 -> 0 | AQ78: =AQ77 -> 0 | AR78: =AR77 -> 0 | AS78: =AS77 -> 0 | AT78: 1 | AU78: =AU77 -> 0 | AV78: =AV77 -> 0
AH79: Achievement Rate | AK79: #DIV/0! | AL79: =(AL71-AL75)/(AL71-AL74) -> #DIV/0! | AM79: =(AM71-AM75)/(AM71-AM74) -> #DIV/0! | AN79: =(AN71-AN75)/(AN71-AN74) -> #DIV/0! | AO79: =(AO71-AO75)/(AO71-AO74) -> #DIV/0! | AP79: =(AP71-AP75)/(AP71-AP74) -> #DIV/0! | AQ79: =(AQ71-AQ75)/(AQ71-AQ74) -> #DIV/0! | AR79: =(AR71-AR75)/(AR71-AR74) -> #DIV/0! | AS79: =(AS71-AS75)/(AS71-AS74) -> #DIV/0! | ... AV79: =(AV71-AV75)/(AV71-AV74) -> #DIV/0!
AH80: Achievement Rate (Conditional) | AK80: 1 | AL80: 0 | AM80: 0 | AN80: 0 | AO80: 0 | AP80: =IF(OR(AP79>=100%),100%,IF(OR(AP79<=0%),0%,AVERAGE(AP79))) -> #DIV/0! | AQ80: =IF(OR(AQ79>=100%),100%,IF(OR(AQ79<=0%),0%,AVERAGE(AQ79))) -> #DIV/0! | AR80: =IF(OR(AR79>=100%),100%,IF(OR(AR79<=0%),0%,AVERAGE(AR79))) -> #DIV/0! | AS80: =IF(OR(AS79>=100%),100%,IF(OR(AS79<=0%),0%,AVERAGE(AS79))) -> #DIV/0! | AT80: =IF(OR(AT79>=100%),100%,IF(OR(AT79<=0%),0%,AVERAGE(AT79))) -> #DIV/0! | AU80: =IF(OR(AU79>=100%),100%,IF(OR(AU79<=0%),0%,AVERAGE(AU79))) -> #DIV/0! | AV80: =IF(OR(AV79>=100%),100%,IF(OR(AV79<=0%),0%,AVERAGE(AV79))) -> #DIV/0!
AG81: 5 | AH81: WEIGHTED AVERAGE | AK81: =AK80*0.05 -> 0.05 | AL81: =AL80*0.05 -> 0 | AM81: =AM80*0.05 -> 0 | AN81: =AN80*0.05 -> 0 | AO81: =AO80*0.05 -> 0 | AP81: =AP80*0.05 -> #DIV/0! | AQ81: =AQ80*0.05 -> #DIV/0! | AR81: =AR80*0.05 -> #DIV/0! | ... AV81: =AV80*0.05 -> #DIV/0!
...

Sheet YF
A2: =AO204 -> 1 | B2: Action Plan | E2: Division / Section: | I2: YF | R2: Ref. No.: | Z2: Approved (sign)
B3: Theme | E3: Responsible Person | I3: Team Members | R3: Date Prepared: | T3: 45544 | Z3: ESM/EAN/RNS
A4: Key 11 | B4: Quality Assurance System | E4: Jezelle Alcantara | I4: Vilma Medrano / Axl Villanueva | R4: Approval: | T4: GBR
A5: Aiming for Improvement | B5: Slogan | E5: Area | I5: Objective | R5: Evaluation Factor Customer Claim | T5: Evaluation Factor First Pass Yield / Dppm | V5: Evaluation Factor First Pass Yield / Dppm (Automotive) | X5: Evaluation Factor OQC LAR / Dppm | Z5: Evaluation Factor OQC LAR / Dppm (Automotive) | AB5: Evaluation Factor Loss Cost Ratio to Sales
B6: Let's apply QA system on countermeasures at the source | E6: YF | I6: <> Boost Efficiency and Quality with Higher YIELD / Lower DPPM for Better Performance | R6: FY23 | S6: FY 24Tgt | T6: FY23 | U6: FY 24Tgt | V6: FY23 | W6: FY 24Tgt | X6: FY23 | Y6: FY 24Tgt | Z6: FY23 | AA6: FY 24Tgt | AB6: FY23 | AC6: FY 24Tgt
I7: <> Enhance Outgoing LAR while Decreasing DPPM | R7: Class A 0 | S7: Class A 0 | T7: 0.9996 | U7: 0.9998 | V7: 0.9995 | W7: 0.9996 | X7: 1 | Y7: 1 | Z7: 1 | AA7: 1 | AB7: 0.0003 | AC7: 0.0003
I8: <> Customer Satisfaction Enhancement: Minimizing Customer’s Complaints
I9: <> Attainment of Company-Wide Loss Cost Ratio to Sales Goal
R10: Class B/C 0 | S10: Class B/C 0 | T10: 432 | U10: 367 | V10: 472 | W10: 420 | X10: 0 | Y10: 0 | Z10: 0 | AA10: 0
A13: No | B13: Actions | E13: Person | F13: Apr | G13: May | H13: Jun | I13: Jul | J13: Aug | K13: Sep | L13: Oct | M13: Nov | N13: Dec | O13: Jan | P13: Feb | Q13: Mar | R13: Follow-up by Responsible Person | Z13: Comments from Manager
A14: 1 | B14: System Improvement through automation <>Automation of product dimension result | E14: Belen/Axl | R14: April | S14: Implement item 3,4 & 5 to minimize loss cost | Z14: GBR | AA14: Monitor the progress of Plans & Programs action items to sustain on-target performance
B15: Automation of In-line Monitoring and quality feedback recording | E15: RDM / Belen/ Jezelle | R15: 45413 | S15: Start to plan for item#6 to speed up the processing of shipment label | Z15: GBR | AA15: Include the defect escalation monitoring during weekly line performance assessment
B16: Limit set-up material to a maximum 5pcs or 1 panel | E16: Vilma/Axl | R16: 45444 | S16: Continue to implement all actions derived in Q1 to maintain the good performance. | Z16: GBR | AA16: Focus on yield Dppm reduction -system enhancement 1) control of prod NG by controlling the parts usage during machine conversion 2) change the defect escalation rule for immediate analysis & improvement
B17: Elevate the Defect Escalation System from 3 to 1 piece for the major process (eg. machine & visual) | E17: Vilma/Axl/ Belen | R17: 45474 | S17: To complete the system of Inline monitoring and quality feedback recording( Automation) | Z17: GBR | AA17: Focus on yield Dppm reduction through system enhancement 1) control of prod NG by controlling the parts usage during machine conversion 2) change the defect escalation rule for immediate analysis & improvement
B18: Implement 1 day lead time from the date received  Existing: Once parts /materials are complete | E18: Acel | R18: 45505 | S18: The system for improvement through automation during measurement data gathering has been completed. Need to monitor the effectiveness of this system. | Z18: GBR
B19: Process simplification of shipment label | E19: Vilma /Axl /Belen
B20: Implement CAPA validation onsite using 8D report validation process | E20: RDM / Belen/ Jezelle
AJ50: Pink cell should be updated
AH51: YF Section
AH52: 1.) Customer Claim (Class A) | AJ52: 45352 | AK52: 45383 | AL52: 45413 | AM52: 45444 | AN52: 45474 | AO52: 45505 | AP52: 45536 | AQ52: 45566 | AR52: 45597 | AS52: 45627 | AT52: 45658 | AU52: 45689 | AV52: 45717
AH53: =(AV53-AJ53)/12 -> 0 | AJ53: =$AV$53 -> 0 | AK53: =AJ53+$AH$53 -> 0 | AL53: =AK53+$AH$53 -> 0 | AM53: =AL53+$AH$53 -> 0 | AN53: =AM53+$AH$53 -> 0 | AO53: =AN53+$AH$53 -> 0 | AP53: =AO53+$AH$53 -> 0 | AQ53: =AP53+$AH$53 -> 0 | AR53: =AQ53+$AH$53 -> 0 | ... AU53: =AT53+$AH$53 -> 0 | AV53: 0
AH54: =(AV54-AJ54)/12 -> 0 | AI54: Performance | AJ54: =$AV$53 -> 0 | AK54: =AJ54+$AH$54 -> 0 | AL54: =AK54+$AH$54 -> 0 | AM54: =AL54+$AH$54 -> 0 | AN54: =AM54+$AH$54 -> 0 | AO54: =AN54+$AH$54 -> 0 | AP54: =AO54+$AH$54 -> 0 | AQ54: =AP54+$AH$54 -> 0 | AR54: =AQ54+$AH$54 -> 0 | ... AU54: =AT54+$AH$54 -> 0 | AV54: =AV53-(AV53-AV56)*0.5 -> 0
AH55: =(AV55-AJ55)/12 -> 0 | AI55: Performance | AJ55: =$AV$53 -> 0 | AK55: =AJ55+$AH$55 -> 0 | AL55: =AK55+$AH$55 -> 0 | AM55: =AL55+$AH$55 -> 0 | AN55: =AM55+$AH$55 -> 0 | AO55: =AN55+$AH$55 -> 0 | AP55: =AO55+$AH$55 -> 0 | AQ55: =AP55+$AH$55 -> 0 | AR55: =AQ55+$AH$55 -> 0 | ... AU55: =AT55+$AH$55 -> 0 | AV55: =AV53-(AV53-AV56)*0.8 -> 0
AH56: =(AV56-AJ56)/12 -> 0 | AI56: Performance | AJ56: =$AV$53 -> 0 | AK56: =AJ56+$AH$56 -> 0 | AL56: =AK56+$AH$56 -> 0 | AM56: =AL56+$AH$56 -> 0 | AN56: =AM56+$AH$56 -> 0 | AO56: =AN56+$AH$56 -> 0 | AP56: =AO56+$AH$56 -> 0 | AQ56: =AP56+$AH$56 -> 0 | AR56: =AQ56+$AH$56 -> 0 | ... AU56: =AT56+$AH$56 -> 0 | AV56: 0
AH57: Accum. Actual Performance | AK57: =AK59 -> 0 | AL57: =AK57+AL59 -> 0 | AM57: =AL57+AM59 -> 0 | AN57: =AM57+AN59 -> 0 | AO57: =AN57+AO59 -> 0 | AP57: =AO57+AP59 -> 0 | AQ57: =AP57+AQ59 -> 0 | AR57: =AQ57+AR59 -> 0 | AS57: =AR57+AS59 -> 0 | ... AU57: =AT57+AU59 -> 0 | AV57: 0
AH59: Actual Performance | AK59: 0 | AL59: 0 | AM59: 0 | AN59: 0 | AO59: 0
AK60: =AK59 -> 0 | AL60: =AL59 -> 0 | AM60: =AM59 -> 0 | AN60: =AN59 -> 0 | AO60: =AO59 -> 0 | AP60: =AP59 -> 0 | AQ60: =AQ59 -> 0 | AR60: =AR59 -> 0 | ... AV60: =AV59 -> 0
AH61: Achievement Rate | AK61: 1 | AL61: 1 | AM61: 1 | AN61: 1 | AO61: 1 | AP61: 1 | AQ61: 1 | AR61: 1 | AS61: 1 | AT61: 1 | AU61: 1 | AV61: 1
Q62: ` | AH62: Achievement Rate (Conditional) | AK62: 1 | AL62: =IF(OR(AL61>=100%),100%,IF(OR(AL61<=0%),0%,AVERAGE(AL61))) -> 1 | AM62: =IF(OR(AM61>=100%),100%,IF(OR(AM61<=0%),0%,AVERAGE(AM61))) -> 1 | AN62: =IF(OR(AN61>=100%),100%,IF(OR(AN61<=0%),0%,AVERAGE(AN61))) -> 1 | AO62: =IF(OR(AO61>=100%),100%,IF(OR(AO61<=0%),0%,AVERAGE(AO61))) -> 1 | AP62: =IF(OR(AP61>=100%),100%,IF(OR(AP61<=0%),0%,AVERAGE(AP61))) -> 1 | AQ62: =IF(OR(AQ61>=100%),100%,IF(OR(AQ61<=0%),0%,AVERAGE(AQ61))) -> 1 | AR62: =IF(OR(AR61>=100%),100%,IF(OR(AR61<=0%),0%,AVERAGE(AR61))) -> 1 | AS62: =IF(OR(AS61>=100%),100%,IF(OR(AS61<=0%),0%,AVERAGE(AS61))) -> 1 | ... AV62: =IF(OR(AV61>=100%),100%,IF(OR(AV61<=0%),0%,AVERAGE(AV61))) -> 1
AH63: WEIGHTED AVERAGE | AK63: =AK62*0.05 -> 0.05 | AL63: =AL62*0.05 -> 0.05 | AM63: =AM62*0.05 -> 0.05 | AN63: =AN62*0.05 -> 0.05 | AO63: =AO62*0.05 -> 0.05 | AP63: =AP62*0.05 -> 0.05 | AQ63: =AQ62*0.05 -> 0.05 | AR63: =AR62*0.05 -> 0.05 | ... AV63: =AV62*0.05 -> 0.05
AH66: 2) Customer Claim (Class B/C) | AJ66: 45352 | AK66: 45383 | AL66: 45413 | AM66: 45444 | AN66: 45474 | AO66: 45505 | AP66: 45536 | AQ66: 45566 | AR66: 45597 | AS66: 45627 | AT66: 45658 | AU66: 45689 | AV66: 45717
AH67: =(AV67-AJ67)/12 -> 0 | AJ67: =AV67 -> 0 | AK67: =AJ67+$AH$67 -> 0 | AL67: =AK67+$AH$67 -> 0 | AM67: =AL67+$AH$67 -> 0 | AN67: =AM67+$AH$67 -> 0 | AO67: =AN67+$AH$67 -> 0 | AP67: =AO67+$AH$67 -> 0 | AQ67: =AP67+$AH$67 -> 0 | AR67: =AQ67+$AH$67 -> 0 | ... AU67: =AT67+$AH$67 -> 0 | AV67: 0
AH68: =(AV68-AJ68)/12 -> 0 | AI68: Performance | AJ68: =AV67 -> 0 | AK68: =AJ68+$AH$68 -> 0 | AL68: =AK68+$AH$68 -> 0 | AM68: =AL68+$AH$68 -> 0 | AN68: =AM68+$AH$68 -> 0 | AO68: =AN68+$AH$68 -> 0 | AP68: =AO68+$AH$68 -> 0 | AQ68: =AP68+$AH$68 -> 0 | AR68: =AQ68+$AH$68 -> 0 | ... AU68: =AT68+$AH$68 -> 0 | AV68: =AV67-(AV67-AV70)*0.5 -> 0
AH69: =(AV69-AJ69)/12 -> 0 | AI69: Performance | AJ69: =AV67 -> 0 | AK69: =AJ69+$AH$69 -> 0 | AL69: =AK69+$AH$69 -> 0 | AM69: =AL69+$AH$69 -> 0 | AN69: =AM69+$AH$69 -> 0 | AO69: =AN69+$AH$69 -> 0 | AP69: =AO69+$AH$69 -> 0 | AQ69: =AP69+$AH$69 -> 0 | AR69: =AQ69+$AH$69 -> 0 | ... AU69: =AT69+$AH$69 -> 0 | AV69: =AV67-(AV67-AV70)*0.8 -> 0
AH70: =(AV70-AJ70)/12 -> 0 | AI70: Performance | AJ70: =AV67 -> 0 | AK70: =AJ70+$AH$70 -> 0 | AL70: =AK70+$AH$70 -> 0 | AM70: =AL70+$AH$70 -> 0 | AN70: =AM70+$AH$70 -> 0 | AO70: =AN70+$AH$70 -> 0 | AP70: =AO70+$AH$70 -> 0 | AQ70: =AP70+$AH$70 -> 0 | AR70: =AQ70+$AH$70 -> 0 | ... AU70: =AT70+$AH$70 -> 0 | AV70: 0
AH71: Accum. Actual Performance | AK71: =AK73 -> 0 | AL71: =AK71+AL73 -> 0 | AM71: =AL71+AM73 -> 0 | AN71: =AM71+AN73 -> 0 | AO71: =AN71+AO73 -> 0 | AP71: =AO71+AP73 -> 0 | AQ71: =AP71+AQ73 -> 0 | AR71: =AQ71+AR73 -> 0 | AS71: =AR71+AS73 -> 0 | ... AV71: =AU71+AV73 -> 0
AH73: Actual Performance | AK73: 0 | AL73: 0 | AM73: 0 | AN73: 0 | AO73: 0 | AP73: 0 | AQ73: 0 | AR73: 0 | AS73: 0 | AT73: 0 | AU73: 0 | AV73: 0
AK74: =AK73 -> 0 | AL74: =AL73 -> 0 | AM74: =AM73 -> 0 | AN74: =AN73 -> 0 | AO74: =AO73 -> 0 | AP74: =AP73 -> 0 | AQ74: =AQ73 -> 0 | AR74: =AR73 -> 0 | ... AV74: =AV73 -> 0
AH75: Achievement Rate | AK75: 1 | AL75: 1 | AM75: 1 | AN75: 1 | AO75: 1 | AP75: 1 | AQ75: 1 | AR75: 1 | AS75: 1 | AT75: 1 | AU75: 1 | AV75: 1
AH76: Achievement Rate (Conditional) | AK76: 1 | AL76: 1 | AM76: 1 | AN76: =IF(OR(AN75>=100%),100%,IF(OR(AN75<=0%),0%,AVERAGE(AN75))) -> 1 | AO76: =IF(OR(AO75>=100%),100%,IF(OR(AO75<=0%),0%,AVERAGE(AO75))) -> 1 | AP76: =IF(OR(AP75>=100%),100%,IF(OR(AP75<=0%),0%,AVERAGE(AP75))) -> 1 | AQ76: =IF(OR(AQ75>=100%),100%,IF(OR(AQ75<=0%),0%,AVERAGE(AQ75))) -> 1 | AR76: =IF(OR(AR75>=100%),100%,IF(OR(AR75<=0%),0%,AVERAGE(AR75))) -> 1 | AS76: =IF(OR(AS75>=100%),100%,IF(OR(AS75<=0%),0%,AVERAGE(AS75))) -> 1 | AT76: =IF(OR(AT75>=100%),100%,IF(OR(AT75<=0%),0%,AVERAGE(AT75))) -> 1 | AU76: =IF(OR(AU75>=100%),100%,IF(OR(AU75<=0%),0%,AVERAGE(AU75))) -> 1 | AV76: =IF(OR(AV75>=100%),100%,IF(OR(AV75<=0%),0%,AVERAGE(AV75))) -> 1
...

Sheet PPD
A2: =AM163 -> 0.74988915 | B2: Action Plan | E2: Division / Section: | I2: PPS | R2: Ref. No.: | X2: Approved (sign)
B3: Theme | E3: Responsible Person | I3: Team Members | R3: Date Prepared: | T3: 45544 | X3: ESM/EAN/RNS
A4: Key 11 | B4: Quality Assurance System | E4: Belen Perez | I4: Nolasco M. / Mark Del Rosario / Miily L. / Jo C. / Lovie A | R4: Approval: | T4: APM
A5: Aiming for Improvement | B5: Slogan | E5: Area | I5: Objective | R5: Evaluation Factor Customer Claim | T5: Evaluation Factor First Pass Yield / Dppm | V5: Evaluation Factor OQC LAR / Dppm | X5: Evaluation Factor Loss Cost Ratio to Sales | Z5: Evaluation Factor Customer Claim (Internal)
B6: Let's apply QA system on countermeasures at the source | E6: PPS | I6: <> Boost Efficiency and Quality with Higher YIELD / Lower DPPM for Better Performance | R6: FY23 | S6: FY 24Tgt | T6: FY23 | U6: FY 24Tgt | V6: FY23 | W6: FY 24Tgt | X6: FY23 | Y6: FY 24Tgt | Z6: FY23 | AA6: FY 24Tgt
I7: <> Enhance Outgoing LAR while Decreasing DPPM | R7: Class A 2 | S7: Class A 2 | T7: 0.9972 | U7: 0.9974 | V7: 0.9996 | W7: 0.9998 | X7: 0.005 | Y7: 0.0045 | Z7: 20 | AA7: 15
I8: <> Customer Satisfaction Enhancement: Minimizing Customer’s Complaints
I9: <> Attainment of Company-Wide Loss Cost Ratio to Sales Goal
R10: Class B/C 0 | S10: Class B/C 0 | T10: 2758 | U10: 2649 | V10: 26 | W10: 1.4
A13: No | B13: Actions | E13: Person | F13: Apr | G13: May | H13: Jun | I13: Jul | J13: Aug | K13: Sep | L13: Oct | M13: Nov | N13: Dec | O13: Jan | P13: Feb | Q13: Mar | R13: Follow-up by Responsible Person | X13: Comments from Manager
A14: 1 | B14: Improve product condition of Mold insert products (FRS018 & FUS006) | E14: APM / HAV / RDM | R14: 45383 | S14: Revision of work instructions and incorporation of the standard set-up sample to be disposed | X14: 45383 | Y14: Consider to improve yield performance of CN174D products
A15: 2 | B15: Strengthen machine or product qualification and inspection for grinded parts | E15: Nolasco Mendoza / Belen Perez | R15: 45414 | S15: Continue to implement immediate and preventive actions for internal claims and loss cost to maintain the quality performance of PPS. | X15: 45414 | Y15: Need to implement automation skill - Schedule on June-2024
A16: 3 | B16: Enhance product qualification for Molding parts prior mass production | E16: APM, FMC, HAV/ RDM | R16: 45446 | S16: Initiate initial management program | X16: 45446 | Y16: Monitor loss cost and Generate action on LAR
A17: 4 | B17: Enhancement of product and die set evaluation | E17: T. Nozaki / APM / FMC / RDM / HAV | R17: 45474 | S17: Need to provide concrete analysis and immediate actions for the Bubbless problem to control the increasing trend of internal claim and Off target LAR Yield | X17: 45474 | Y17: Continue the update for intial management.
R18: 45505 | S18: Focus the improvement for lot-out and loss cost for both PPD-CN and PPD-TS products | X18: 45505 | Y18: Initiate improvement on HF106-03#IN Monitor thr result after the improvement
AH50: Pink cell should be updated
AF51: PPS Section
AF52: 1.) Customer Claim (Class A) | AH52: 45352 | AI52: 45383 | AJ52: 45413 | AK52: 45444 | AL52: 45474 | AM52: 45505 | AN52: 45536 | AO52: 45566 | AP52: 45597 | AQ52: 45627 | AR52: 45658 | AS52: 45689 | AT52: 45717
AF53: =(AT53-AH53)/12 -> 0 | AH53: =AT53 -> 2 | AI53: 2 | AJ53: =AI53+$AF$53 -> 2 | AK53: =AJ53+$AF$53 -> 2 | AL53: =AK53+$AF$53 -> 2 | AM53: =AL53+$AF$53 -> 2 | AN53: =AM53+$AF$53 -> 2 | AO53: =AN53+$AF$53 -> 2 | AP53: =AO53+$AF$53 -> 2 | AQ53: =AP53+$AF$53 -> 2 | ... AS53: =AR53+$AF$53 -> 2 | AT53: 2
AF54: =(AT54-AH54)/12 -> 0 | AG54: Performance | AH54: =AT54 -> 2 | AI54: 2 | AJ54: =AI54+$AF$54 -> 2 | AK54: =AJ54+$AF$54 -> 2 | AL54: =AK54+$AF$54 -> 2 | AM54: =AL54+$AF$54 -> 2 | AN54: =AM54+$AF$54 -> 2 | AO54: =AN54+$AF$54 -> 2 | AP54: =AO54+$AF$54 -> 2 | AQ54: =AP54+$AF$54 -> 2 | ... AS54: =AR54+$AF$54 -> 2 | AT54: 2
AF55: =(AT55-AH55)/12 -> 0 | AG55: Performance | AH55: =AT55 -> 2 | AI55: 2 | AJ55: =AI55+$AF$55 -> 2 | AK55: =AJ55+$AF$55 -> 2 | AL55: =AK55+$AF$55 -> 2 | AM55: =AL55+$AF$55 -> 2 | AN55: =AM55+$AF$55 -> 2 | AO55: =AN55+$AF$55 -> 2 | AP55: =AO55+$AF$55 -> 2 | AQ55: =AP55+$AF$55 -> 2 | ... AS55: =AR55+$AF$55 -> 2 | AT55: =AT53-(AT53-AT56)*0.8 -> 2
AF56: =(AT56-AH56)/12 -> 0 | AG56: Performance | AH56: =AT56 -> 2 | AI56: 2 | AJ56: =AI56+$AF$56 -> 2 | AK56: =AJ56+$AF$56 -> 2 | AL56: =AK56+$AF$56 -> 2 | AM56: =AL56+$AF$56 -> 2 | AN56: =AM56+$AF$56 -> 2 | AO56: =AN56+$AF$56 -> 2 | AP56: =AO56+$AF$56 -> 2 | AQ56: =AP56+$AF$56 -> 2 | ... AS56: =AR56+$AF$56 -> 2 | AT56: 2
AF57: Accum. Actual Performance | AI57: 0 | AJ57: =AI57+AJ59 -> 0 | AK57: =AJ57+AK59 -> 0 | AL57: =AK57+AL59 -> 0 | AM57: =AL57+AM59 -> 1 | AN57: =AM57+AN59 -> 1 | AO57: =AN57+AO59 -> 1 | AP57: =AO57+AP59 -> 1 | AQ57: =AP57+AQ59 -> 1 | ... AT57: =AS57+AT59 -> 1
AF59: Actual Performance | AI59: 0 | AJ59: 0 | AK59: 0 | AL59: 0 | AM59: 1
AI60: 0 | AJ60: =AJ59 -> 0 | AK60: =AK59 -> 0 | AL60: =AL59 -> 0 | AM60: =AM59 -> 1 | AN60: =AN59 -> 0 | AO60: =AO59 -> 0 | AP60: =AP59 -> 0 | AQ60: =AQ59 -> 0 | ... AT60: =AT59 -> 0
AF61: Achievement Rate | AI61: 1 | AJ61: 1 | AK61: 1 | AL61: 1 | AM61: =(AM53-AM57)/(AM53-AM56) -> #DIV/0! | AN61: =(AN53-AN57)/(AN53-AN56) -> #DIV/0! | AO61: =(AO53-AO57)/(AO53-AO56) -> #DIV/0! | AP61: =(AP53-AP57)/(AP53-AP56) -> #DIV/0! | AQ61: =(AQ53-AQ57)/(AQ53-AQ56) -> #DIV/0! | AR61: =(AR53-AR57)/(AR53-AR56) -> #DIV/0! | AS61: =(AS53-AS57)/(AS53-AS56) -> #DIV/0! | AT61: =(AT53-AT57)/(AT53-AT56) -> #DIV/0!
AF62: Achievement Rate (Conditional) | AI62: 1 | AJ62: =IF(OR(AJ61>=100%),100%,IF(OR(AJ61<=0%),0%,AVERAGE(AJ61))) -> 1 | AK62: =IF(OR(AK61>=100%),100%,IF(OR(AK61<=0%),0%,AVERAGE(AK61))) -> 1 | AL62: =IF(OR(AL61>=100%),100%,IF(OR(AL61<=0%),0%,AVERAGE(AL61))) -> 1 | AM62: 0 | AN62: =IF(OR(AN61>=100%),100%,IF(OR(AN61<=0%),0%,AVERAGE(AN61))) -> #DIV/0! | AO62: =IF(OR(AO61>=100%),100%,IF(OR(AO61<=0%),0%,AVERAGE(AO61))) -> #DIV/0! | AP62: =IF(OR(AP61>=100%),100%,IF(OR(AP61<=0%),0%,AVERAGE(AP61))) -> #DIV/0! | AQ62: =IF(OR(AQ61>=100%),100%,IF(OR(AQ61<=0%),0%,AVERAGE(AQ61))) -> #DIV/0! | AR62: =IF(OR(AR61>=100%),100%,IF(OR(AR61<=0%),0%,AVERAGE(AR61))) -> #DIV/0! | AS62: =IF(OR(AS61>=100%),100%,IF(OR(AS61<=0%),0%,AVERAGE(AS61))) -> #DIV/0! | AT62: =IF(OR(AT61>=100%),100%,IF(OR(AT61<=0%),0%,AVERAGE(AT61))) -> #DIV/0!
AF63: WEIGHTED AVERAGE | AI63: 0.05 | AJ63: =AJ62*0.05 -> 0.05 | AK63: =AK62*0.05 -> 0.05 | AL63: =AL62*0.05 -> 0.05 | AM63: =AM62*0.05 -> 0 | AN63: =AN62*0.05 -> #DIV/0! | AO63: =AO62*0.05 -> #DIV/0! | AP63: =AP62*0.05 -> #DIV/0! | AQ63: =AQ62*0.05 -> #DIV/0! | ... AT63: =AT62*0.05 -> #DIV/0!
AF66: 2) Customer Claim (Class B/C) | AH66: 45352 | AI66: 45383 | AJ66: 45413 | AK66: 45444 | AL66: 45474 | AM66: 45505 | AN66: 45536 | AO66: 45566 | AP66: 45597 | AQ66: 45627 | AR66: 45658 | AS66: 45689 | AT66: 45717
